2024-01-05 23:06:26,596 INFO main -     list_cmd_handler Получен запрос от @Skwiz, chat_id = 358708535
2024-01-05 23:06:40,481 INFO main -      bug_cmd_handler Получен запрос от @Skwiz, chat_id = 358708535
2024-01-05 23:06:56,616 INFO main - web_app_data_handler Получены данные {"title":"2","descr":"3","project":"ФЦОД-М","request_number":"1"}, chat_id = 358708535
2024-01-05 23:06:59,759 INFO main - web_app_data_handler Создан дефект: 43250
2024-01-05 23:07:19,337 INFO main -   attachment_handler file_path= https://api.telegram.org/file/bot6925490738:AAFn0ofUoo5tCSw4-xpLAF8y7s6NwOaSOyQ/photos/file_12.jpg, size= 5895, bug_id = 43250
2024-01-05 23:07:40,210 INFO main -   attachment_handler Успешно добавлен аттач к 43250, chat_id = 358708535
2024-01-05 23:17:19,011 INFO _application -                 stop Application is stopping. This might take a moment.
2024-01-05 23:17:19,011 INFO _application -                 stop Application.stop() complete
2024-01-05 23:17:45,880 INFO _application -                start Application started
2024-01-05 23:17:47,878 INFO main -      bug_cmd_handler Получен запрос от @Skwiz, chat_id = 358708535
2024-01-05 23:17:48,777 INFO main -   add_attach_handler Получен запрос от @Skwiz, chat_id = 358708535
2024-01-05 23:18:08,430 INFO main - wi_number_entry_handler Получен запрос от @Skwiz, chat_id = 358708535, wi: 1000
2024-01-05 23:18:11,113 ERROR _application -        process_error No error handlers are registered, logging exception.
Traceback (most recent call last):
  File "C:\Users\demid\PycharmProjects\pycord-bot\venv\lib\site-packages\urllib3\connection.py", line 203, in _new_conn
    sock = connection.create_connection(
  File "C:\Users\demid\PycharmProjects\pycord-bot\venv\lib\site-packages\urllib3\util\connection.py", line 60, in create_connection
    for res in socket.getaddrinfo(host, port, family, socket.SOCK_STREAM):
  File "C:\Python310\lib\socket.py", line 955, in getaddrinfo
    for res in _socket.getaddrinfo(host, port, family, type, proto, flags):
socket.gaierror: [Errno 11001] getaddrinfo failed

The above exception was the direct cause of the following exception:

Traceback (most recent call last):
  File "C:\Users\demid\PycharmProjects\pycord-bot\venv\lib\site-packages\urllib3\connectionpool.py", line 790, in urlopen
    response = self._make_request(
  File "C:\Users\demid\PycharmProjects\pycord-bot\venv\lib\site-packages\urllib3\connectionpool.py", line 496, in _make_request
    conn.request(
  File "C:\Users\demid\PycharmProjects\pycord-bot\venv\lib\site-packages\urllib3\connection.py", line 395, in request
    self.endheaders()
  File "C:\Python310\lib\http\client.py", line 1277, in endheaders
    self._send_output(message_body, encode_chunked=encode_chunked)
  File "C:\Python310\lib\http\client.py", line 1037, in _send_output
    self.send(msg)
  File "C:\Python310\lib\http\client.py", line 975, in send
    self.connect()
  File "C:\Users\demid\PycharmProjects\pycord-bot\venv\lib\site-packages\urllib3\connection.py", line 243, in connect
    self.sock = self._new_conn()
  File "C:\Users\demid\PycharmProjects\pycord-bot\venv\lib\site-packages\urllib3\connection.py", line 210, in _new_conn
    raise NameResolutionError(self.host, self, e) from e
urllib3.exceptions.NameResolutionError: <urllib3.connection.HTTPConnection object at 0x000002BFBA248FD0>: Failed to resolve 'ztfs-2017' ([Errno 11001] getaddrinfo failed)

The above exception was the direct cause of the following exception:

Traceback (most recent call last):
  File "C:\Users\demid\PycharmProjects\pycord-bot\venv\lib\site-packages\requests\adapters.py", line 486, in send
    resp = conn.urlopen(
  File "C:\Users\demid\PycharmProjects\pycord-bot\venv\lib\site-packages\urllib3\connectionpool.py", line 844, in urlopen
    retries = retries.increment(
  File "C:\Users\demid\PycharmProjects\pycord-bot\venv\lib\site-packages\urllib3\util\retry.py", line 515, in increment
    raise MaxRetryError(_pool, url, reason) from reason  # type: ignore[arg-type]
urllib3.exceptions.MaxRetryError: HTTPConnectionPool(host='ztfs-2017', port=8080): Max retries exceeded with url: /tfs/Fintech/MIR/_apis/wit/workitems/1000?api-version=4.1 (Caused by NameResolutionError("<urllib3.connection.HTTPConnection object at 0x000002BFBA248FD0>: Failed to resolve 'ztfs-2017' ([Errno 11001] getaddrinfo failed)"))

During handling of the above exception, another exception occurred:

Traceback (most recent call last):
  File "C:\Users\demid\PycharmProjects\pycord-bot\venv\lib\site-packages\telegram\ext\_application.py", line 1234, in process_update
    await coroutine
  File "C:\Users\demid\PycharmProjects\pycord-bot\venv\lib\site-packages\telegram\ext\_conversationhandler.py", line 857, in handle_update
    new_state: object = await handler.handle_update(
  File "C:\Users\demid\PycharmProjects\pycord-bot\venv\lib\site-packages\telegram\ext\_basehandler.py", line 157, in handle_update
    return await self.callback(update, context)
  File "C:\Users\demid\PycharmProjects\pycord-bot\main.py", line 270, in wi_number_entry_handler
    if tfs.check_wi_exists(workitemId):
  File "C:\Users\demid\PycharmProjects\pycord-bot\tfs_utility.py", line 178, in check_wi_exists
    resp = requests.get(get_uri, auth=requests_kerberos.HTTPKerberosAuth())
  File "C:\Users\demid\PycharmProjects\pycord-bot\venv\lib\site-packages\requests\api.py", line 73, in get
    return request("get", url, params=params, **kwargs)
  File "C:\Users\demid\PycharmProjects\pycord-bot\venv\lib\site-packages\requests\api.py", line 59, in request
    return session.request(method=method, url=url, **kwargs)
  File "C:\Users\demid\PycharmProjects\pycord-bot\venv\lib\site-packages\requests\sessions.py", line 589, in request
    resp = self.send(prep, **send_kwargs)
  File "C:\Users\demid\PycharmProjects\pycord-bot\venv\lib\site-packages\requests\sessions.py", line 703, in send
    r = adapter.send(request, **kwargs)
  File "C:\Users\demid\PycharmProjects\pycord-bot\venv\lib\site-packages\requests\adapters.py", line 519, in send
    raise ConnectionError(e, request=request)
requests.exceptions.ConnectionError: HTTPConnectionPool(host='ztfs-2017', port=8080): Max retries exceeded with url: /tfs/Fintech/MIR/_apis/wit/workitems/1000?api-version=4.1 (Caused by NameResolutionError("<urllib3.connection.HTTPConnection object at 0x000002BFBA248FD0>: Failed to resolve 'ztfs-2017' ([Errno 11001] getaddrinfo failed)"))
2024-01-05 23:21:28,037 INFO _application -                start Application started
2024-01-05 23:21:33,203 INFO main -      bug_cmd_handler Получен запрос от @Skwiz, chat_id = 358708535
2024-01-05 23:21:34,056 INFO main -   add_attach_handler Получен запрос от @Skwiz, chat_id = 358708535
2024-01-05 23:21:37,418 INFO main - wi_number_entry_handler Получен запрос от @Skwiz, chat_id = 358708535, wi: 1000
2024-01-05 23:21:51,368 INFO main -      bug_cmd_handler Получен запрос от @Skwiz, chat_id = 358708535
2024-01-05 23:22:41,727 INFO main -   add_attach_handler Получен запрос от @Skwiz, chat_id = 358708535
2024-01-05 23:22:43,673 INFO main - wi_number_entry_handler Получен запрос от @Skwiz, chat_id = 358708535, wi: 43250
2024-01-05 23:23:01,301 INFO main -   attachment_handler file_path= https://api.telegram.org/file/bot6925490738:AAFn0ofUoo5tCSw4-xpLAF8y7s6NwOaSOyQ/photos/file_12.jpg, size= 5895, bug_id = 43250
2024-01-06 01:06:56,461 INFO _application -                 stop Application is stopping. This might take a moment.
2024-01-06 01:06:56,462 INFO _application -                 stop Application.stop() complete
2024-01-06 02:12:37,691 INFO _application -                start Application started
2024-01-06 02:12:52,915 INFO main -     discord_redirect Redirecting to webhook
2024-01-06 02:13:46,868 INFO main -     discord_redirect Redirecting to webhook
2024-01-06 02:13:55,432 INFO main -     discord_redirect Redirecting to webhook
2024-01-06 02:18:11,406 INFO _application -                 stop Application is stopping. This might take a moment.
2024-01-06 02:18:11,406 INFO _application -                 stop Application.stop() complete
2024-01-06 02:18:14,001 INFO _application -                start Application started
2024-01-06 02:18:27,138 INFO main -     discord_redirect Redirecting to webhook
2024-01-06 13:23:47,695 ERROR _updater -  _network_loop_retry Error while getting Updates: httpx.ConnectError: [Errno 11001] getaddrinfo failed
